Workbook

Sheet Registro_QC_CT
A1: CONTROL DE CALIDAD TOMOGRAFÍA COMPUTARIZADA - MEDICIONES MANUALES
A2: Trabajo de Grado - Karol Andrea Peña Arango
A4: Fecha de Evaluación: | D4: Institución / Sede: | G4: Persona que evalúa:
A6: 1. NÚMERO CT DEL AGUA Y RUIDO (Sección de Uniformidad)
A7: Medición / Corte | B7: Media HU Medida | C7: Desv. est. σ (HU), solo en el corte central | D7: Ruido (%) = σ / 1000 × 100 | E7: Criterio Media | F7: Criterio ruido | G7: Estado Media HU | H7: Estado Ruido | I7: Observaciones
A8: Corte 1 | D8: =IF(ISBLANK(C8),"",C8/1000*100) | E8: 0 ± 5 HU | G8: =IF(ISBLANK(B8),"",IF(AND(B8>=-5,B8<=5),"CUMPLE","NO CUMPLE"))
A9: Corte 2 | D9: =IF(ISBLANK(C9),"",C9/1000*100) | E9: 0 ± 5 HU | G9: =IF(ISBLANK(B9),"",IF(AND(B9>=-5,B9<=5),"CUMPLE","NO CUMPLE"))
A10: Corte 3 | D10: =IF(ISBLANK(C10),"",C10/1000*100) | E10: 0 ± 5 HU | G10: =IF(ISBLANK(B10),"",IF(AND(B10>=-5,B10<=5),"CUMPLE","NO CUMPLE"))
A11: Corte 4 | D11: =IF(ISBLANK(C11),"",C11/1000*100) | E11: 0 ± 5 HU | G11: =IF(ISBLANK(B11),"",IF(AND(B11>=-5,B11<=5),"CUMPLE","NO CUMPLE"))
A12: Corte 5 | D12: =IF(ISBLANK(C12),"",C12/1000*100) | E12: 0 ± 5 HU | G12: =IF(ISBLANK(B12),"",IF(AND(B12>=-5,B12<=5),"CUMPLE","NO CUMPLE"))
A13: RESULTADO: | B13: =IF(COUNT(B8:B12)=0,"",AVERAGE(B8:B12)) | C13: =IF(COUNT(C8:C12)=1,SUM(C8:C12),"") | D13: =IF(C13="","",C13/1000*100) | E13: 0 ± 5 HU | F13: ± 25 % de la línea base | G13: =IF(B13="","",IF(AND(B13>=-5,B13<=5),"CUMPLE","NO CUMPLE")) | H13: =IF(COUNT(C8:C12)=0,"",IF(COUNT(C8:C12)>1,"ESCRIBIR σ EN UN SOLO CORTE",IF(ISBLANK(D14),"SIN REFERENCIA",IF(ABS(D13-D14)<=0.25*D14,"CUMPLE","NO CUMPLE")))) | I13: La media HU es el promedio de los cortes. El ruido se mide en un solo corte, el central: escriba σ solo en esa fila. Ruido (%) = σ / 1000 × 100.
A14: Línea base del ruido (%), mismo equipo y misma técnica: | I14: Si aún no hay línea base, este control pasa a serlo.
A15: 2. UNIFORMIDAD ESPACIAL (Misma imagen / corte que Sección 1)
A16: Posición ROI | B16: Media HU Medida | C16: ROI Centro (HU) | D16: Diferencia |HU_i - HU_centro| | E16: Tolerancia Máxima | F16: Métrica Global | G16: Estado Uniformidad | H16: - | I16: Observaciones
A17: Centro | C17: =$B$17 -> 0 | D17: 0 | E17: ≤ 10 HU | F17: ΔCT máx: | G17: ESTADO GLOBAL:
A18: Periférico Superior | C18: =$B$17 -> 0 | D18: =ABS(B18-C18) -> 0 | E18: ≤ 10 HU | F18: =MAX(D18:D21) -> 0 | G18: =IF(ISBLANK(B17),"",IF(F18<=10,"CUMPLE","NO CUMPLE"))
A19: Periférico Derecho | C19: =$B$17 -> 0 | D19: =ABS(B19-C19) -> 0 | E19: ≤ 10 HU
A20: Periférico Inferior | C20: =$B$17 -> 0 | D20: =ABS(B20-C20) -> 0 | E20: ≤ 10 HU
A21: Periférico Izquierdo | C21: =$B$17 -> 0 | D21: =ABS(B21-C21) -> 0 | E21: ≤ 10 HU
A23: 3. LINEALIDAD DEL NÚMERO CT (Varillas de Calibración)
A24: Material | B24: HU nominal del fabricante (informativo) | C24: HU Medido | D24: Δ nominal (medido − nominal, informativa) | E24: Tolerancia (vs línea base del equipo) | F24: Estado Material | G24: Métrica Regresión | H24: Valor | I24: Estado Linealidad | J24: HU línea base del equipo (1.ª medición, mismo kV) | K24: ΔCT vs línea base (HU)
A25: CORTE 1
A26: Polietileno (PE) | B26: -92 | D26: =IF(ISBLANK(C26),"",C26-B26) | E26: ± 5 HU | F26: =IF(ISBLANK(C26),"",IF(J26="","SIN REFERENCIA",IF(ABS(C26-J26)<=5,"CUMPLE","NO CUMPLE"))) | G26: Coeficiente R² (informativo): | H26: =IF(COUNT(C26:C31)<6,"",RSQ(C26:C31,B26:B31)) | I26: ESTADO LINEALIDAD: | J26: =IF(ISBLANK(J47),"",J47) | K26: =IF(OR(ISBLANK(C26),J26="",J26=0),"",C26-J26)
A27: Poliestireno (PS) | B27: -24 | D27: =IF(ISBLANK(C27),"",C27-B27) | E27: ± 5 HU | F27: =IF(ISBLANK(C27),"",IF(J27="","SIN REFERENCIA",IF(ABS(C27-J27)<=5,"CUMPLE","NO CUMPLE"))) | I27: =IF(COUNT(C26:C31)<6,"",IF(COUNTIF(F26:F31,"NO CUMPLE")=0,"CUMPLE","NO CUMPLE")) | J27: =IF(ISBLANK(J48),"",J48) | K27: =IF(OR(ISBLANK(C27),J27="",J27=0),"",C27-J27)
A28: Agua (Fondo) | B28: 0 | D28: =IF(ISBLANK(C28),"",C28-B28) | E28: ± 5 HU | F28: =IF(ISBLANK(C28),"",IF(ABS(C28)<=5,"CUMPLE","NO CUMPLE")) | G28: Respuesta monótona: | H28: =IF(COUNT(C26:C31)<6,"",IF(AND(C26<C27,C27<C28,C28<C29,C29<C30,C30<C31),"SÍ","NO")) | J28: =IF(ISBLANK(J49),"",J49)
A29: Nylon | B29: 92 | D29: =IF(ISBLANK(C29),"",C29-B29) | E29: ± 5 HU | F29: =IF(ISBLANK(C29),"",IF(J29="","SIN REFERENCIA",IF(ABS(C29-J29)<=5,"CUMPLE","NO CUMPLE"))) | G29: Δ conjunto vs nominal (info): | H29: =IF(COUNT(C26:C31)<6,"",MAX(ABS(SMALL(C26:C31,1)-SMALL(B26:B31,1)),ABS(SMALL(C26:C31,2)-SMALL(B26:B31,2)),ABS(SMALL(C26:C31,3)-SMALL(B26:B31,3)),ABS(SMALL(C26:C31,4)-SMALL(B26:B31,4)),ABS(SMALL(C26:C31,5)-SMALL(B26:B31,5)),ABS(SMALL(C26:C31,6)-SMALL(B26:B31,6)))) | J29: =IF(ISBLANK(J50),"",J50) | K29: =IF(OR(ISBLANK(C29),J29="",J29=0),"",C29-J29)
A30: Policarbonato (PC) | B30: 102 | D30: =IF(ISBLANK(C30),"",C30-B30) | E30: ± 5 HU | F30: =IF(ISBLANK(C30),"",IF(J30="","SIN REFERENCIA",IF(ABS(C30-J30)<=5,"CUMPLE","NO CUMPLE"))) | G30: Plásticos con referencia: | H30: =COUNT(J26,J27,J29,J30,J31)&" de 5" -> 0 de 5 | J30: =IF(ISBLANK(J51),"",J51) | K30: =IF(OR(ISBLANK(C30),J30="",J30=0),"",C30-J30)
A31: PMMA | B31: 120 | D31: =IF(ISBLANK(C31),"",C31-B31) | E31: ± 5 HU | F31: =IF(ISBLANK(C31),"",IF(J31="","SIN REFERENCIA",IF(ABS(C31-J31)<=5,"CUMPLE","NO CUMPLE"))) | J31: =IF(ISBLANK(J52),"",J52) | K31: =IF(OR(ISBLANK(C31),J31="",J31=0),"",C31-J31)
A32: CORTE 2
A33: Polietileno (PE) | B33: -92 | D33: =IF(ISBLANK(C33),"",C33-B33) | E33: ± 5 HU | F33: =IF(ISBLANK(C33),"",IF(J33="","SIN REFERENCIA",IF(ABS(C33-J33)<=5,"CUMPLE","NO CUMPLE"))) | G33: Coeficiente R² (informativo): | H33: =IF(COUNT(C33:C38)<6,"",RSQ(C33:C38,B33:B38)) | I33: ESTADO LINEALIDAD: | J33: =IF(ISBLANK(J47),"",J47) | K33: =IF(OR(ISBLANK(C33),J33="",J33=0),"",C33-J33)
A34: Poliestireno (PS) | B34: -24 | D34: =IF(ISBLANK(C34),"",C34-B34) | E34: ± 5 HU | F34: =IF(ISBLANK(C34),"",IF(J34="","SIN REFERENCIA",IF(ABS(C34-J34)<=5,"CUMPLE","NO CUMPLE"))) | I34: =IF(COUNT(C33:C38)<6,"",IF(COUNTIF(F33:F38,"NO CUMPLE")=0,"CUMPLE","NO CUMPLE")) | J34: =IF(ISBLANK(J48),"",J48) | K34: =IF(OR(ISBLANK(C34),J34="",J34=0),"",C34-J34)
A35: Agua (Fondo) | B35: 0 | D35: =IF(ISBLANK(C35),"",C35-B35) | E35: ± 5 HU | F35: =IF(ISBLANK(C35),"",IF(ABS(C35)<=5,"CUMPLE","NO CUMPLE")) | G35: Respuesta monótona: | H35: =IF(COUNT(C33:C38)<6,"",IF(AND(C33<C34,C34<C35,C35<C36,C36<C37,C37<C38),"SÍ","NO")) | J35: =IF(ISBLANK(J49),"",J49)
A36: Nylon | B36: 92 | D36: =IF(ISBLANK(C36),"",C36-B36) | E36: ± 5 HU | F36: =IF(ISBLANK(C36),"",IF(J36="","SIN REFERENCIA",IF(ABS(C36-J36)<=5,"CUMPLE","NO CUMPLE"))) | G36: Δ conjunto vs nominal (info): | H36: =IF(COUNT(C33:C38)<6,"",MAX(ABS(SMALL(C33:C38,1)-SMALL(B33:B38,1)),ABS(SMALL(C33:C38,2)-SMALL(B33:B38,2)),ABS(SMALL(C33:C38,3)-SMALL(B33:B38,3)),ABS(SMALL(C33:C38,4)-SMALL(B33:B38,4)),ABS(SMALL(C33:C38,5)-SMALL(B33:B38,5)),ABS(SMALL(C33:C38,6)-SMALL(B33:B38,6)))) | J36: =IF(ISBLANK(J50),"",J50) | K36: =IF(OR(ISBLANK(C36),J36="",J36=0),"",C36-J36)
A37: Policarbonato (PC) | B37: 102 | D37: =IF(ISBLANK(C37),"",C37-B37) | E37: ± 5 HU | F37: =IF(ISBLANK(C37),"",IF(J37="","SIN REFERENCIA",IF(ABS(C37-J37)<=5,"CUMPLE","NO CUMPLE"))) | G37: Plásticos con referencia: | H37: =COUNT(J33,J34,J36,J37,J38)&" de 5" -> 0 de 5 | J37: =IF(ISBLANK(J51),"",J51) | K37: =IF(OR(ISBLANK(C37),J37="",J37=0),"",C37-J37)
A38: PMMA | B38: 120 | D38: =IF(ISBLANK(C38),"",C38-B38) | E38: ± 5 HU | F38: =IF(ISBLANK(C38),"",IF(J38="","SIN REFERENCIA",IF(ABS(C38-J38)<=5,"CUMPLE","NO CUMPLE"))) | J38: =IF(ISBLANK(J52),"",J52) | K38: =IF(OR(ISBLANK(C38),J38="",J38=0),"",C38-J38)
A39: CORTE 3
A40: Polietileno (PE) | B40: -92 | D40: =IF(ISBLANK(C40),"",C40-B40) | E40: ± 5 HU | F40: =IF(ISBLANK(C40),"",IF(J40="","SIN REFERENCIA",IF(ABS(C40-J40)<=5,"CUMPLE","NO CUMPLE"))) | G40: Coeficiente R² (informativo): | H40: =IF(COUNT(C40:C45)<6,"",RSQ(C40:C45,B40:B45)) | I40: ESTADO LINEALIDAD: | J40: =IF(ISBLANK(J47),"",J47) | K40: =IF(OR(ISBLANK(C40),J40="",J40=0),"",C40-J40)
A41: Poliestireno (PS) | B41: -24 | D41: =IF(ISBLANK(C41),"",C41-B41) | E41: ± 5 HU | F41: =IF(ISBLANK(C41),"",IF(J41="","SIN REFERENCIA",IF(ABS(C41-J41)<=5,"CUMPLE","NO CUMPLE"))) | I41: =IF(COUNT(C40:C45)<6,"",IF(COUNTIF(F40:F45,"NO CUMPLE")=0,"CUMPLE","NO CUMPLE")) | J41: =IF(ISBLANK(J48),"",J48) | K41: =IF(OR(ISBLANK(C41),J41="",J41=0),"",C41-J41)
A42: Agua (Fondo) | B42: 0 | D42: =IF(ISBLANK(C42),"",C42-B42) | E42: ± 5 HU | F42: =IF(ISBLANK(C42),"",IF(ABS(C42)<=5,"CUMPLE","NO CUMPLE")) | G42: Respuesta monótona: | H42: =IF(COUNT(C40:C45)<6,"",IF(AND(C40<C41,C41<C42,C42<C43,C43<C44,C44<C45),"SÍ","NO")) | J42: =IF(ISBLANK(J49),"",J49)
A43: Nylon | B43: 92 | D43: =IF(ISBLANK(C43),"",C43-B43) | E43: ± 5 HU | F43: =IF(ISBLANK(C43),"",IF(J43="","SIN REFERENCIA",IF(ABS(C43-J43)<=5,"CUMPLE","NO CUMPLE"))) | G43: Δ conjunto vs nominal (info): | H43: =IF(COUNT(C40:C45)<6,"",MAX(ABS(SMALL(C40:C45,1)-SMALL(B40:B45,1)),ABS(SMALL(C40:C45,2)-SMALL(B40:B45,2)),ABS(SMALL(C40:C45,3)-SMALL(B40:B45,3)),ABS(SMALL(C40:C45,4)-SMALL(B40:B45,4)),ABS(SMALL(C40:C45,5)-SMALL(B40:B45,5)),ABS(SMALL(C40:C45,6)-SMALL(B40:B45,6)))) | J43: =IF(ISBLANK(J50),"",J50) | K43: =IF(OR(ISBLANK(C43),J43="",J43=0),"",C43-J43)
...

Sheet Resumen_QC
A1: INFORME RESUMEN Y CONFORMIDAD DE CONTROL DE CALIDAD TC
A3: Prueba / Parámetro Evaluado | B3: Valor Medido / Métrica | C3: Tolerancia / Criterio | D3: Estado Parcial | E3: Nivel de Impacto | F3: Dictamen / Recomendación
A4: Número CT del agua (HU) | B4: =Registro_QC_CT!B13 | C4: 0 ± 5 HU | D4: =Registro_QC_CT!G13 | E4: Alto | F4: Calibración de escala HU
A5: Ruido relativo (%) | B5: =Registro_QC_CT!D13 | C5: ± 25 % de la línea base | D5: =Registro_QC_CT!H13 | E5: Alto | F5: Dosis / Corriente de tubo / Algoritmo
A6: Uniformidad Espacial (ΔCT máx) | B6: =Registro_QC_CT!F18 -> 0 | C6: ≤ 10 HU | D6: =Registro_QC_CT!G18 | E6: Alto | F6: Artefactos en rosquilla / Filtros de reconst.
A7: Linealidad CT (mayor |ΔCT| vs línea base, HU) | B7: =IF(COUNT(Registro_QC_CT!K47:K52)=0,"",MAX(MAX(Registro_QC_CT!K47:K52),-MIN(Registro_QC_CT!K47:K52))) | C7: Varillas ± 5 HU vs línea base; agua 0 ± 5 HU | D7: =Registro_QC_CT!I48 | E7: Crítico | F7: Calibración detector / Tabla de materiales
A8: Resolución Alto Contraste (Visual) | B8: =Registro_QC_CT!D57 | C8: =Registro_QC_CT!E57 -> ≥ 5 pl/cm (protocolos distintos de tórax) | D8: =Registro_QC_CT!F57 | E8: Medio | F8: Enfoque del tubo / Matriz / Filtro alto contraste
A9: Resolución Bajo Contraste | B9: N/A | C9: Vs Línea Base | D9: =Registro_QC_CT!E62 -> NO APLICA | E9: Medio | F9: Sin contraste en cavidades
A10: Espesor de Corte Promedio | B10: =Registro_QC_CT!D69 | C10: Tabla 6 de la guía | D10: =Registro_QC_CT!F69 | E10: Medio | F10: Colimación / Ancho de haz
A11: Dispersión entre láminas (dato) | B11: =Registro_QC_CT!G69 | C11: Sin criterio | D11: NO APLICA | E11: Bajo | F11: Alineación del fantoma / Mesa
A12: Verificación Tamaño de Píxel | B12: =Registro_QC_CT!D73 | C12: < 2.0 % | D12: =Registro_QC_CT!F73 | E12: Crítico | F12: Geometría DICOM / Calibración de campo (FOV)
A14: DIAGNOSTICO Y ESTADO GLOBAL DEL TOMÓGRAFO
A15: DICTAMEN FINAL: | B15: =IF(COUNTIF(D4:D12,"CUMPLE")+COUNTIF(D4:D12,"NO CUMPLE")=0,"SIN DATOS",IF(COUNTIF(D4:D12,"NO CUMPLE")=0,"CUMPLE LOS CRITERIOS EVALUADOS","EQUIPO REQUIERE INTERVENCIÓN DE MANTENIMIENTO / CALIBRACIÓN")) -> SIN DATOS

Sheet Referencia_Tolerancias
A1: TABLAS DE REFERENCIA Y VALORES ESPERADOS (PRO-CT AAPM)
A3: Linealidad: valores nominales del fabricante (informativos) y criterio contra la línea base del equipo
A4: Material | B4: HU Nominal Fabricante | C4: Criterio | D4: Nota
A5: Polietileno (PE) | B5: -92 | C5: ± 5 HU vs línea base del equipo | D5: Nominal informativo, sin criterio
A6: Poliestireno (PS) | B6: -24 | C6: ± 5 HU vs línea base del equipo | D6: Nominal informativo, sin criterio
A7: Agua (Fondo) | B7: 0 | C7: 0 ± 5 HU | D7: El 0 HU es la definición de la escala
A8: Nylon | B8: 92 | C8: ± 5 HU vs línea base del equipo | D8: Nominal informativo, sin criterio
A9: Policarbonato (PC) | B9: 102 | C9: ± 5 HU vs línea base del equipo | D9: Nominal informativo, sin criterio
A10: PMMA | B10: 120 | C10: ± 5 HU vs línea base del equipo | D10: Nominal informativo, sin criterio
A12: Criterios vigentes
A13: Número CT del agua | B13: 0 ± 5 HU | C13: AAPM / ARCAL / TECDOC
A14: Ruido | B14: ± 25 % respecto a la línea base (σ de un solo corte) | C14: TECDOC-1958
A15: Uniformidad (ΔCT máx.) | B15: ≤ 10 HU | C15: TECDOC-1958
A16: Resolución de alto contraste | B16: ≥ 5 pl/cm | C16: ≥ 6 pl/cm en protocolos de tórax; el ancho a media altura del alambre es un dato sin criterio
A17: Espesor de corte | B17: Tabla 6 de la guía (TECDOC-1958) | C17: ≤ 1 mm: < nominal + 0,5 mm; 1 a 2 mm: ± 50 %; > 2 mm: ± 1 mm; el promedio y las 3 láminas en tolerancia; la dispersión es un dato
A18: Tamaño de píxel | B18: < 2 % | C18: Recomendado; el módulo no lo evalúa
