Workbook

Sheet Calidad_imagen
A1: CALIDAD DE IMAGEN CON EL FANTOMA MAMMO 156 - MEDICIÓN MANUAL
A2: Trabajo de Grado - Karol Andrea Peña Arango · ARCAL XLIX §4.9.2
A4: Fecha de evaluación: | D4: Institución / sede: | G4: Persona que evalúa:
A5: Equipo (fabricante, modelo, serie): | G5: Imagen (archivo):
A7: 1. TÉCNICA DE ADQUISICIÓN (del encabezado DICOM; imagen procesada FOR PRESENTATION)
A8: kV | B8: Ánodo / filtro | C8: mAs | D8: Modo | E8: Espesor (mm) | F8: Fuerza (N) | G8: DGM (mGy) = encabezado (dGy) × 100 | H8: Ventana usada (WL / WW)
A11: 2. PUNTUACIÓN DE LOS OBJETOS · fibras y masas: 1 / 0.5 / 0 · micros: n.º de partículas vistas (0 a 6)
A12: Objeto | B12: Tamaño nominal (mm) | C12: Respuesta | D12: Puntuación | E12: Contado (regla de corte) | F12: Aporte | G12: Cuenta para artefactos | H12: Último contado | I12: Observaciones
A13: F1 · fibra | B13: 1.56 | D13: =IF(ISBLANK(C13),"",C13) | E13: =IF(D13="","",1) | F13: =IF(D13="","",D13*E13) | G13: =IF(D13="",0,IF(AND(E13=1,D13>0),1,0)) -> 0 | H13: =IF(AND(G13=1,G14=0),"SÍ","")
A14: F2 · fibra | B14: 1.12 | D14: =IF(ISBLANK(C14),"",C14) | E14: =IF(D14="","",IF(AND(E13=1,D13=1),1,0)) | F14: =IF(D14="","",D14*E14) | G14: =IF(D14="",0,IF(AND(E14=1,D14>0),1,0)) -> 0 | H14: =IF(AND(G14=1,G15=0),"SÍ","")
A15: F3 · fibra | B15: 0.89 | D15: =IF(ISBLANK(C15),"",C15) | E15: =IF(D15="","",IF(AND(E14=1,D14=1),1,0)) | F15: =IF(D15="","",D15*E15) | G15: =IF(D15="",0,IF(AND(E15=1,D15>0),1,0)) -> 0 | H15: =IF(AND(G15=1,G16=0),"SÍ","")
A16: F4 · fibra | B16: 0.75 | D16: =IF(ISBLANK(C16),"",C16) | E16: =IF(D16="","",IF(AND(E15=1,D15=1),1,0)) | F16: =IF(D16="","",D16*E16) | G16: =IF(D16="",0,IF(AND(E16=1,D16>0),1,0)) -> 0 | H16: =IF(AND(G16=1,G17=0),"SÍ","")
A17: F5 · fibra | B17: 0.54 | D17: =IF(ISBLANK(C17),"",C17) | E17: =IF(D17="","",IF(AND(E16=1,D16=1),1,0)) | F17: =IF(D17="","",D17*E17) | G17: =IF(D17="",0,IF(AND(E17=1,D17>0),1,0)) -> 0 | H17: =IF(AND(G17=1,G18=0),"SÍ","")
A18: F6 · fibra | B18: 0.4 | D18: =IF(ISBLANK(C18),"",C18) | E18: =IF(D18="","",IF(AND(E17=1,D17=1),1,0)) | F18: =IF(D18="","",D18*E18) | G18: =IF(D18="",0,IF(AND(E18=1,D18>0),1,0)) -> 0 | H18: =IF(G18=1,"SÍ","")
A19: S1 · grupo de micros | B19: 0.54 | D19: =IF(ISBLANK(C19),"",IF(C19>=4,1,IF(C19>=2,0.5,0))) | E19: =IF(D19="","",1) | F19: =IF(D19="","",D19*E19) | G19: =IF(D19="",0,IF(AND(E19=1,D19>0),1,0)) -> 0 | H19: =IF(AND(G19=1,G20=0),"SÍ","")
A20: S2 · grupo de micros | B20: 0.4 | D20: =IF(ISBLANK(C20),"",IF(C20>=4,1,IF(C20>=2,0.5,0))) | E20: =IF(D20="","",IF(AND(E19=1,D19=1),1,0)) | F20: =IF(D20="","",D20*E20) | G20: =IF(D20="",0,IF(AND(E20=1,D20>0),1,0)) -> 0 | H20: =IF(AND(G20=1,G21=0),"SÍ","")
A21: S3 · grupo de micros | B21: 0.32 | D21: =IF(ISBLANK(C21),"",IF(C21>=4,1,IF(C21>=2,0.5,0))) | E21: =IF(D21="","",IF(AND(E20=1,D20=1),1,0)) | F21: =IF(D21="","",D21*E21) | G21: =IF(D21="",0,IF(AND(E21=1,D21>0),1,0)) -> 0 | H21: =IF(AND(G21=1,G22=0),"SÍ","")
A22: S4 · grupo de micros | B22: 0.24 | D22: =IF(ISBLANK(C22),"",IF(C22>=4,1,IF(C22>=2,0.5,0))) | E22: =IF(D22="","",IF(AND(E21=1,D21=1),1,0)) | F22: =IF(D22="","",D22*E22) | G22: =IF(D22="",0,IF(AND(E22=1,D22>0),1,0)) -> 0 | H22: =IF(AND(G22=1,G23=0),"SÍ","")
A23: S5 · grupo de micros | B23: 0.16 | D23: =IF(ISBLANK(C23),"",IF(C23>=4,1,IF(C23>=2,0.5,0))) | E23: =IF(D23="","",IF(AND(E22=1,D22=1),1,0)) | F23: =IF(D23="","",D23*E23) | G23: =IF(D23="",0,IF(AND(E23=1,D23>0),1,0)) -> 0 | H23: =IF(G23=1,"SÍ","")
A24: M1 · masa | B24: 2 | D24: =IF(ISBLANK(C24),"",C24) | E24: =IF(D24="","",1) | F24: =IF(D24="","",D24*E24) | G24: =IF(D24="",0,IF(AND(E24=1,D24>0),1,0)) -> 0 | H24: =IF(AND(G24=1,G25=0),"SÍ","")
A25: M2 · masa | B25: 1 | D25: =IF(ISBLANK(C25),"",C25) | E25: =IF(D25="","",IF(AND(E24=1,D24=1),1,0)) | F25: =IF(D25="","",D25*E25) | G25: =IF(D25="",0,IF(AND(E25=1,D25>0),1,0)) -> 0 | H25: =IF(AND(G25=1,G26=0),"SÍ","")
A26: M3 · masa | B26: 0.75 | D26: =IF(ISBLANK(C26),"",C26) | E26: =IF(D26="","",IF(AND(E25=1,D25=1),1,0)) | F26: =IF(D26="","",D26*E26) | G26: =IF(D26="",0,IF(AND(E26=1,D26>0),1,0)) -> 0 | H26: =IF(AND(G26=1,G27=0),"SÍ","")
A27: M4 · masa | B27: 0.5 | D27: =IF(ISBLANK(C27),"",C27) | E27: =IF(D27="","",IF(AND(E26=1,D26=1),1,0)) | F27: =IF(D27="","",D27*E27) | G27: =IF(D27="",0,IF(AND(E27=1,D27>0),1,0)) -> 0 | H27: =IF(AND(G27=1,G28=0),"SÍ","")
A28: M5 · masa | B28: 0.25 | D28: =IF(ISBLANK(C28),"",C28) | E28: =IF(D28="","",IF(AND(E27=1,D27=1),1,0)) | F28: =IF(D28="","",D28*E28) | G28: =IF(D28="",0,IF(AND(E28=1,D28>0),1,0)) -> 0 | H28: =IF(G28=1,"SÍ","")
A30: Artefactos (objetos con forma de fibra, grupo o masa fuera de su posición)
A31: Tipo de artefacto | B31: Cantidad | C31: Resta en | D31: Puntuación restada
A32: Raya (forma de fibra) | C32: fibras | D32: =IF(COUNT(C13:C18)<6,"",IF(N(B32)=0,0,IF(COUNTIFS(G13:G18,1,D13:D18,0.5)=1,0.5+MIN(B32,SUM(G13:G18))-1,MIN(B32,SUM(G13:G18)))))
A33: Punto brillante (forma de micro) | C33: micros | D33: =IF(COUNT(C19:C23)<5,"",IF(N(B33)=0,0,SUMPRODUCT((H19:H23="SÍ")*(D19:D23-0.5*((C19:C23-B33)>=2)-0.5*((C19:C23-B33)>=4)))))
A34: Mancha redonda (forma de masa) | C34: masas | D34: =IF(COUNT(C24:C28)<5,"",IF(N(B34)=0,0,IF(COUNTIFS(G24:G28,1,D24:D28,0.5)=1,0.5+MIN(B34,SUM(G24:G28))-1,MIN(B34,SUM(G24:G28)))))
A35: Otro (se registra, no resta) | C35: — | D35: —
A37: Totales ARCAL
A38: Tipo | B38: Suma con corte | C38: Restado por artefactos | D38: Total | E38: Mínimo | F38: Estado | G38: Corte en | H38: Total del control anterior (opcional) | I38: Cambio (ARCAL: ≤ 0.5, informativo)
A39: Fibras | B39: =IF(COUNT(C13:C18)<6,"",SUM(F13:F18)) | C39: =IF(B39="","",D32) | D39: =IF(B39="","",B39-C39) | E39: ≥ 4 | F39: =IF(D39="","",IF(D39>=4,"CUMPLE","NO CUMPLE")) | G39: =IF(B39="","",IFERROR(INDEX(A13:A18,MATCH(1,INDEX((D13:D18<1)*1,0),0)),"sin corte")) | I39: =IF(OR(D39="",ISBLANK(H39)),"",D39-H39)
A40: Micros | B40: =IF(COUNT(C19:C23)<5,"",SUM(F19:F23)) | C40: =IF(B40="","",D33) | D40: =IF(B40="","",B40-C40) | E40: ≥ 3 | F40: =IF(D40="","",IF(D40>=3,"CUMPLE","NO CUMPLE")) | G40: =IF(B40="","",IFERROR(INDEX(A19:A23,MATCH(1,INDEX((D19:D23<1)*1,0),0)),"sin corte")) | I40: =IF(OR(D40="",ISBLANK(H40)),"",D40-H40)
A41: Masas | B41: =IF(COUNT(C24:C28)<5,"",SUM(F24:F28)) | C41: =IF(B41="","",D34) | D41: =IF(B41="","",B41-C41) | E41: ≥ 3 | F41: =IF(D41="","",IF(D41>=3,"CUMPLE","NO CUMPLE")) | G41: =IF(B41="","",IFERROR(INDEX(A24:A28,MATCH(1,INDEX((D24:D28<1)*1,0),0)),"sin corte")) | I41: =IF(OR(D41="",ISBLANK(H41)),"",D41-H41)
A44: 3. FONDO Y UNIFORMIDAD · ROI de ~1 cm² en el fondo de la cera de cada celda, libre de objetos
A45: Celda | B45: Objeto de la celda | C45: Media del ROI | D45: Área del ROI (mm²) | E45: Observaciones
A46: 1 | B46: F1 · fibra
A47: 2 | B47: F2 · fibra
A48: 3 | B48: F3 · fibra
...

Sheet CAE_repetibilidad
A1: REPETIBILIDAD DEL CONTROL AUTOMÁTICO DE LA EXPOSICIÓN - MEDICIÓN MANUAL
A2: 5 exposiciones seguidas del PMMA con el control automático activado y la misma técnica · prueba adaptada a imágenes procesadas (TECDOC-1958 §4.7)
A4: Fecha de evaluación: | D4: Institución / sede: | G4: Persona que evalúa:
A5: Equipo (fabricante, modelo, serie): | G5: Placas de PMMA:
A8: 1. TÉCNICA, DOSIS Y ROI DE 20 × 20 mm (4 cm²) A 60 mm DE LA PARED TORÁCICA, CENTRADA A LO ALTO
A9: Exposición | B9: Archivo | C9: Hora | D9: kV | E9: Ánodo / filtro | F9: Modo | G9: Corriente I (mA) | H9: Tiempo t (ms) | I9: Carga Q = I·t/1000 (mAs) | J9: mAs del encabezado (redondeado) | K9: Espesor (mm) | L9: Fuerza (N) | M9: DGM (mGy) = encabezado (dGy) × 100 | N9: ESD (mGy) | O9: Media Ī del ROI | P9: DE σ del ROI | Q9: SNR = Ī / σ
A10: 1 | I10: =IF(OR(ISBLANK(G10),ISBLANK(H10)),"",G10*H10/1000) | Q10: =IF(OR(ISBLANK(O10),ISBLANK(P10)),"",O10/P10)
A11: 2 | I11: =IF(OR(ISBLANK(G11),ISBLANK(H11)),"",G11*H11/1000) | Q11: =IF(OR(ISBLANK(O11),ISBLANK(P11)),"",O11/P11)
A12: 3 | I12: =IF(OR(ISBLANK(G12),ISBLANK(H12)),"",G12*H12/1000) | Q12: =IF(OR(ISBLANK(O12),ISBLANK(P12)),"",O12/P12)
A13: 4 | I13: =IF(OR(ISBLANK(G13),ISBLANK(H13)),"",G13*H13/1000) | Q13: =IF(OR(ISBLANK(O13),ISBLANK(P13)),"",O13/P13)
A14: 5 | I14: =IF(OR(ISBLANK(G14),ISBLANK(H14)),"",G14*H14/1000) | Q14: =IF(OR(ISBLANK(O14),ISBLANK(P14)),"",O14/P14)
A15: Media | H15: =IF(COUNT(H10:H14)<5,"",AVERAGE(H10:H14)) | I15: =IF(COUNT(I10:I14)<5,"",AVERAGE(I10:I14)) | M15: =IF(COUNT(M10:M14)<5,"",AVERAGE(M10:M14)) | N15: =IF(COUNT(N10:N14)<5,"",AVERAGE(N10:N14)) | O15: =IF(COUNT(O10:O14)<5,"",AVERAGE(O10:O14)) | P15: =IF(COUNT(P10:P14)<5,"",AVERAGE(P10:P14)) | Q15: =IF(COUNT(Q10:Q14)<5,"",AVERAGE(Q10:Q14))
A16: CV = s / x̄ × 100 (%) | H16: =IF(COUNT(H10:H14)<5,"",STDEV(H10:H14)/AVERAGE(H10:H14)*100) | I16: =IF(COUNT(I10:I14)<5,"",STDEV(I10:I14)/AVERAGE(I10:I14)*100) | M16: =IF(COUNT(M10:M14)<5,"",STDEV(M10:M14)/AVERAGE(M10:M14)*100) | N16: =IF(COUNT(N10:N14)<5,"",STDEV(N10:N14)/AVERAGE(N10:N14)*100) | O16: =IF(COUNT(O10:O14)<5,"",STDEV(O10:O14)/AVERAGE(O10:O14)*100) | P16: =IF(COUNT(P10:P14)<5,"",STDEV(P10:P14)/AVERAGE(P10:P14)*100) | Q16: =IF(COUNT(Q10:Q14)<5,"",STDEV(Q10:Q14)/AVERAGE(Q10:Q14)*100)
A17: Desv. máx. = máx|xᵢ − x̄| / x̄ × 100 (%) | H17: =IF(COUNT(H10:H14)<5,"",MAX(MAX(H10:H14)-AVERAGE(H10:H14),AVERAGE(H10:H14)-MIN(H10:H14))/AVERAGE(H10:H14)*100) | I17: =IF(COUNT(I10:I14)<5,"",MAX(MAX(I10:I14)-AVERAGE(I10:I14),AVERAGE(I10:I14)-MIN(I10:I14))/AVERAGE(I10:I14)*100) | M17: =IF(COUNT(M10:M14)<5,"",MAX(MAX(M10:M14)-AVERAGE(M10:M14),AVERAGE(M10:M14)-MIN(M10:M14))/AVERAGE(M10:M14)*100) | N17: =IF(COUNT(N10:N14)<5,"",MAX(MAX(N10:N14)-AVERAGE(N10:N14),AVERAGE(N10:N14)-MIN(N10:N14))/AVERAGE(N10:N14)*100) | O17: =IF(COUNT(O10:O14)<5,"",MAX(MAX(O10:O14)-AVERAGE(O10:O14),AVERAGE(O10:O14)-MIN(O10:O14))/AVERAGE(O10:O14)*100) | P17: =IF(COUNT(P10:P14)<5,"",MAX(MAX(P10:P14)-AVERAGE(P10:P14),AVERAGE(P10:P14)-MIN(P10:P14))/AVERAGE(P10:P14)*100) | Q17: =IF(COUNT(Q10:Q14)<5,"",MAX(MAX(Q10:Q14)-AVERAGE(Q10:Q14),AVERAGE(Q10:Q14)-MIN(Q10:Q14))/AVERAGE(Q10:Q14)*100)
A19: 2. CRITERIOS DE ACEPTACIÓN (de este trabajo, adaptados del TECDOC-1958 §4.7 a imágenes procesadas)
A20: Criterio | B20: Valor | C20: Tolerancia | D20: Estado
A21: La serie es una repetición: una sola combinación de kV, ánodo/filtro y modo | B21: =IF(COUNTA(D10:D14)<5,"",IF(AND(COUNTIF(D10:D14,D10)=5,COUNTIF(E10:E14,E10)=5,COUNTIF(F10:F14,F10)=5),"1 combinación","varias")) | C21: 1 combinación | D21: =IF(B21="","",IF(B21="1 combinación","CUMPLE","NO CUMPLE"))
A22: CV de la carga Q (%) | B22: =I16 | C22: ≤ 5 % | D22: =IF(B22="","",IF(B22<=5,"CUMPLE","NO CUMPLE"))
A23: CV de la DGM (%) | B23: =M16 | C23: ≤ 5 % | D23: =IF(B23="","",IF(B23<=5,"CUMPLE","NO CUMPLE"))
A24: CV del SNR (%) | B24: =Q16 | C24: ≤ 5 % | D24: =IF(B24="","",IF(B24<=5,"CUMPLE","NO CUMPLE"))
A27: 3. REFERENCIA DEL EQUIPO: serie completada más antigua con la misma técnica (kV ± 0.5, ánodo/filtro igual, espesor ± 2 mm)
A28: La primera serie de cada técnica no se compara: queda como referencia.
A29: Serie de referencia (fecha, archivo):
A30: Medida | B30: Media de esta serie | C30: Media de la referencia | D30: Δ = (x̄ − x̄ref) / x̄ref × 100 (%) | E30: Tolerancia | F30: Estado
A31: Carga Q (mAs) | B31: =I15 | D31: =IF(OR(B31="",ISBLANK(C31)),"",(B31-C31)/C31*100) | E31: ± 15 % | F31: =IF(B31="","",IF(ISBLANK(C31),"SIN REFERENCIA",IF(ABS(D31)<=15,"CUMPLE","NO CUMPLE")))
A32: DGM (mGy) | B32: =M15 | D32: =IF(OR(B32="",ISBLANK(C32)),"",(B32-C32)/C32*100) | E32: ± 15 % | F32: =IF(B32="","",IF(ISBLANK(C32),"SIN REFERENCIA",IF(ABS(D32)<=15,"CUMPLE","NO CUMPLE")))
A33: SNR | B33: =Q15 | D33: =IF(OR(B33="",ISBLANK(C33)),"",(B33-C33)/C33*100) | E33: ± 15 % | F33: =IF(B33="","",IF(ISBLANK(C33),"SIN REFERENCIA",IF(ABS(D33)<=15,"CUMPLE","NO CUMPLE")))
A35: La carga real es Q = I · t / 1000, porque el mAs del encabezado viene redondeado a un entero y esconde la variación. El módulo quita la variación lenta del fondo antes de calcular σ; a mano σ sale algo mayor y el SNR algo menor, así que conviene medir siempre de la misma forma. La dosis glandular media (DGM) viene en el encabezado en dGy (campo Organ Dose): multiplicarla por 100 para escribirla en mGy. Hora, tiempo, dosis en la entrada, media y desviación estándar del ROI son informativos.

Sheet CAE_compensacion
A1: COMPENSACIÓN DEL CONTROL AUTOMÁTICO DE LA EXPOSICIÓN - MEDICIÓN MANUAL
A2: Una imagen por espesor de PMMA con el control automático activado (20, 45 y 70 mm) · prueba descriptiva, sin criterio (TECDOC-1958 §4.8 adaptada)
A4: Fecha de evaluación: | D4: Institución / sede: | G4: Persona que evalúa:
A5: Equipo (fabricante, modelo, serie):
A8: 1. TOMAS ORDENADAS DE MENOR A MAYOR ESPESOR COMPRIMIDO · ROI de 20 × 20 mm a 60 mm de la pared torácica (informativo)
A9: Toma | B9: Láminas usadas | C9: Espesor comprimido (mm) | D9: kV | E9: Ánodo / filtro | F9: Corriente I (mA) | G9: Tiempo t (ms) | H9: Carga Q (mAs) | I9: DGM (mGy) = encabezado (dGy) × 100 | J9: ESD (mGy) | K9: Media Ī del ROI | L9: DE σ del ROI | M9: SNR = Ī / σ | N9: Archivo
A10: 1 | H10: =IF(OR(ISBLANK(F10),ISBLANK(G10)),"",F10*G10/1000) | M10: =IF(OR(ISBLANK(K10),ISBLANK(L10)),"",K10/L10)
A11: 2 | H11: =IF(OR(ISBLANK(F11),ISBLANK(G11)),"",F11*G11/1000) | M11: =IF(OR(ISBLANK(K11),ISBLANK(L11)),"",K11/L11)
A12: 3 | H12: =IF(OR(ISBLANK(F12),ISBLANK(G12)),"",F12*G12/1000) | M12: =IF(OR(ISBLANK(K12),ISBLANK(L12)),"",K12/L12)
A13: 4 | H13: =IF(OR(ISBLANK(F13),ISBLANK(G13)),"",F13*G13/1000) | M13: =IF(OR(ISBLANK(K13),ISBLANK(L13)),"",K13/L13)
A14: 5 | H14: =IF(OR(ISBLANK(F14),ISBLANK(G14)),"",F14*G14/1000) | M14: =IF(OR(ISBLANK(K14),ISBLANK(L14)),"",K14/L14)
A16: Control de espesores: | B16: =IF(COUNT(C10:C14)<2,"",IF(SUMPRODUCT((C10:C14<>"")/COUNTIF(C10:C14,C10:C14&""))<COUNTA(C10:C14),"Hay espesores repetidos: no son tomas a espesores distintos, repetir una","Espesores distintos"))
A18: Sin criterio de aceptación: se registran la técnica que elige el control automático, la carga y la dosis para cada espesor. El criterio del protocolo (TECDOC-1958 §4.8) compara la relación señal diferencia ruido de un objeto de aluminio sobre el PMMA con la de la toma de 45 mm, y las imágenes actuales no tienen ese objeto. El SNR de la imagen procesada no sirve para comparar espesores, porque el procesamiento iguala el ruido.

Sheet Resumen_QC
A1: INFORME RESUMEN Y CONFORMIDAD DEL CONTROL DE CALIDAD EN MAMOGRAFÍA
A3: Prueba / parámetro | B3: Valor medido | C3: Tolerancia | D3: Estado | E3: Origen
A4: Calidad de imagen · Fibras | B4: =Calidad_imagen!D39 | C4: ≥ 4 | D4: =Calidad_imagen!F39 | E4: ARCAL XLIX §4.9.2
A5: Calidad de imagen · Grupos de microcalcificaciones | B5: =Calidad_imagen!D40 | C5: ≥ 3 | D5: =Calidad_imagen!F40 | E5: ARCAL XLIX §4.9.2
A6: Calidad de imagen · Masas | B6: =Calidad_imagen!D41 | C6: ≥ 3 | D6: =Calidad_imagen!F41 | E6: ARCAL XLIX §4.9.2
A7: Calidad de imagen · Uniformidad U (%) | B7: =Calidad_imagen!C66 | C7: sin veredicto | D7: NO APLICA | E7: línea base del equipo
A8: Calidad de imagen · CV de las celdas (%) | B8: =Calidad_imagen!C67 | C8: sin veredicto | D8: NO APLICA | E8: línea base del equipo
A9: Repetibilidad del control automático · Una sola combinación de técnica | B9: =CAE_repetibilidad!B21 | C9: 1 combinación | D9: =CAE_repetibilidad!D21 | E9: de este trabajo
A10: Repetibilidad del control automático · CV de la carga (%) | B10: =CAE_repetibilidad!B22 | C10: ≤ 5 % | D10: =CAE_repetibilidad!D22 | E10: de este trabajo (adaptado del TECDOC-1958 §4.7)
A11: Repetibilidad del control automático · CV de la DGM (%) | B11: =CAE_repetibilidad!B23 | C11: ≤ 5 % | D11: =CAE_repetibilidad!D23 | E11: de este trabajo (adaptado del TECDOC-1958 §4.7)
A12: Repetibilidad del control automático · CV del SNR (%) | B12: =CAE_repetibilidad!B24 | C12: ≤ 5 % | D12: =CAE_repetibilidad!D24 | E12: de este trabajo (adaptado del TECDOC-1958 §4.7)
A13: Repetibilidad del control automático · Δ carga vs referencia (%) | B13: =CAE_repetibilidad!D31 | C13: ± 15 % | D13: =CAE_repetibilidad!F31 | E13: de este trabajo (TECDOC 4.7 adaptado)
A14: Repetibilidad del control automático · Δ DGM vs referencia (%) | B14: =CAE_repetibilidad!D32 | C14: ± 15 % | D14: =CAE_repetibilidad!F32 | E14: de este trabajo (TECDOC 4.7 adaptado)
A15: Repetibilidad del control automático · Δ SNR vs referencia (%) | B15: =CAE_repetibilidad!D33 | C15: ± 15 % | D15: =CAE_repetibilidad!F33 | E15: de este trabajo (TECDOC 4.7 adaptado)
A16: Compensación del control automático · Compensación del CAE | B16: descriptiva | C16: sin criterio | D16: NO APLICA | E16: Criterio pendiente del objeto de aluminio
A18: DICTAMEN: | B18: =IF(COUNTIF(D4:D15,"NO CUMPLE")>0,"EQUIPO REQUIERE INTERVENCIÓN / REVISIÓN",IF(COUNTIF(D4:D15,"CUMPLE")=0,"SIN DATOS","CUMPLE LOS CRITERIOS EVALUADOS")) -> SIN DATOS
A20: Los criterios marcados «de este trabajo» son provisionales: no vienen de un protocolo y se revisan con la línea base de la institución. Las pruebas del control automático se evalúan sobre imágenes procesadas (FOR PRESENTATION) y no reemplazan las pruebas del TECDOC-1958 §4.7 y §4.8.

Sheet Referencia_Tolerancias
A1: CRITERIOS VIGENTES
A3: Prueba | B3: Criterio | C3: Origen
A4: Calidad de imagen · puntuación | B4: Fibras ≥ 4, grupos de microcalcificaciones ≥ 3, masas ≥ 3 | C4: ARCAL XLIX §4.9.2
A5: Calidad de imagen · puntuación por objeto | B5: Fibras: 1 completa, 0.5 más de la mitad, 0 menos. Grupos: 1 si se ven ≥ 4 de 6, 0.5 si 2 o 3, 0 si < 2. Masas: 1 completa y circular, 0.5 parcial, 0 no se ve | C5: ARCAL XLIX §4.9.2
A6: Calidad de imagen · cambio entre controles | B6: Ningún total cambia más de 0,5 puntos (el módulo aún no lo evalúa) | C6: ARCAL XLIX
A7: Calidad de imagen · uniformidad | B7: U y CV sin veredicto; se guardan como línea base del equipo | C7: sin criterio publicado
A8: Repetibilidad del control automático · repetición | B8: Una sola combinación de kV, ánodo/filtro y modo | C8: de este trabajo
A9: Repetibilidad del control automático · repetibilidad | B9: CV ≤ 5 % de la carga, la DGM y el SNR | C9: de este trabajo (adaptado del TECDOC-1958 §4.7)
A10: Repetibilidad del control automático · línea base | B10: Desviación ≤ 15 % respecto a la referencia del equipo | C10: de este trabajo, provisional (TECDOC-1958 §4.7)
A11: Compensación del control automático | B11: Sin criterio (descriptiva) | C11: Criterio pendiente del objeto de aluminio
